<?xml version="1.0"?>
<robot xmlns:xacro="http://www.ros.org/wiki/xacro" name="robot">

    <xacro:include filename="inertial_macros.xacro" />

    <material name="Black">
        <color rgba="0 0 0 0.95"/> 
    </material>
    <material name="White">
        <color rgba="1 1 1 1"/> 
    </material>
    <material name="Blue">
        <color rgba="0 0 1 1"/>
    </material>
    <material name="Yellow">
        <color rgba="1 0.4 0 1"/>
    </material>

    <link name="base_footprint">
        
    </link>

    <link name="base_link">
    
    </link>
    
    <joint name="base_footprint_joint" type="fixed">
        <parent link="base_footprint"/>
        <child link="base_link"/>
        <origin xyz="0 0 0.074" rpy="0 0 0"/>
    </joint>


    <joint name ="chassis_joint" type="fixed">
        <parent link="base_link"/>
        <child link="chassis"/>
        <origin xyz="-0.1 0 0"/>
    </joint>

    <link name="chassis">

        <visual>
            <origin xyz="0.3 0 0.15"/> 
            <geometry>
                <box size="0.6 0.485 0.3"/>
            </geometry>
            <material name="White"/> 
        </visual>

        
        <collision>
            <origin xyz="0.3 0 0.15"/> 
            <geometry>
                <box size="0.6 0.485 0.3"/>
            </geometry>
        </collision>

        <xacro:inertial_box mass="5.0" x="0.6" y="0.485" z="0.3">
            <origin xyz="0.3 0 0.15" rpy="0 0 0"/>
        </xacro:inertial_box>

    </link>
    <gazebo reference="chassis">
        <material>Gazebo/White</material>
    </gazebo> 

    <joint name="caster_wheel_joint" type="fixed">
        <parent link="base_link"/>
        <child link="caster_wheel"/>
        <origin xyz="0.35 0 0" rpy="0 0 0"/>
    </joint>

    <link name="caster_wheel">
        <visual>
            <geometry>
                <sphere radius="0.074" />
            </geometry>
            <material name="black"/>
        </visual>

        <collision>
            <geometry>
                <sphere radius="0.074"/>
            </geometry>
        </collision>

        <xacro:inertial_sphere mass="0.5"  radius="0.074">
            <origin xyz="0 0 0" rpy="0 0 0"/>
        </xacro:inertial_sphere>

    </link>
    <gazebo reference="caster_wheel">
        <material>Gazebo/Black</material>
        <mu1 value="0.001"/>
        <mu2 value="0.001"/>
    </gazebo>

    <joint name="left_wheel_joint" type="continuous">
        <parent link="base_link" />
        <child link="left_wheel" />
        <origin xyz="0.0 0.2675 0.0" rpy="-1.5708 0 0"/>
        <axis xyz="0 0 1"/>
    </joint>

    <link name="left_wheel">
        <visual>
            <origin rpy="0 0 0" xyz="0 0 0" />
            <geometry>
                <cylinder radius="0.074" length="0.043"/>
            </geometry>
            <material name="Blue"/> 
        </visual>

        <collision>
            <origin rpy="0 0 0" xyz="0 0 0" />
            <geometry>
                <cylinder radius="0.074" length="0.043"/>
            </geometry>
        </collision>

        <xacro:inertial_cylinder mass="0.5" length="0.043" radius="0.074">
            <origin xyz="0 0 0" rpy="0 0 0"/>
        </xacro:inertial_cylinder>

    </link> 
    <gazebo reference="left_wheel">
        <material>Gazebo/Blue</material>
    </gazebo>

    <joint name="right_wheel_joint" type="continuous">
        <parent link="base_link" />
        <child link="right_wheel" />
        <origin xyz="0.0 -0.2675 0.0" rpy="1.5708 0 0"/>
        <axis xyz="0 0 -1"/>
    </joint>

    <link name="right_wheel">
        <visual>
            <origin rpy="0 0 0" xyz="0 0 0" />
            <geometry>
                <cylinder radius="0.074" length="0.043"/>
            </geometry>
            <material name="Blue"/> 
        </visual>

        <collision>
            <origin rpy="0 0 0" xyz="0 0 0" />
            <geometry>
                <cylinder radius="0.074" length="0.043"/>
            </geometry>
        </collision>

        <xacro:inertial_cylinder mass="0.5" length="0.043" radius="0.074">
            <origin xyz="0 0 0" rpy="0 0 0"/>
        </xacro:inertial_cylinder>

        
    </link>
    <gazebo reference="right_wheel">
        <material>Gazebo/Blue</material>
    </gazebo>

    

   <!--<joint name="laser_joint" type="fixed">
        <origin xyz="0.555 0 0.325" rpy="0 0 0" />
        <parent link="chassis" />
        <child link="laser" />
    </joint>

    <link name="laser">

        <visual>
        <origin rpy="0 0 -1.5708" xyz="0 0 0"/>
        <geometry>
            <mesh filename="package://bot_demo/stl/rplidar.stl" scale="0.001 0.001 0.001"/>
        </geometry>
        <material name="Yellow"/>
        </visual>

        <collision>
        <origin rpy="0 0 0" xyz="0 0 0"/>
        <geometry>
            <mesh filename="package://bot_demo/stl/rplidar.stl" scale="0.001 0.001 0.001"/>
        </geometry>
        </collision>
        
    </link>
    <gazebo reference="laser">
        <material>Gazebo/Yellow</material>
    </gazebo>-->

</robot>